Workbook

Sheet Customer
A1: ID | B1: Year_Birth | C1: Education | D1: Marital_Status | E1: Income | F1: Income (K) | G1: Kidhome | H1: Teenhome | I1: Dt_Customer | J1: Recency | K1: MntFruits | L1: MntSweetProducts | M1: NumWebPurchases | N1: NumStorePurchases | O1: Age | P1: Total Amount | Q1: Total Purchases | R1: Total Kids
A2: 5524 | B2: 1957 | C2: Graduation | D2: Single | E2: 58138 | F2: =E2/1000 -> 58.138 | G2: 0 | H2: 0 | I2: 41156 | J2: 58 | K2: {=VLOOKUP(A2,Sales!$A$1:$E$2241,{2,3,4,5},0)} -> 88 | L2: 88 | M2: 8 | N2: 4 | O2: =2025-B2 -> 68 | P2: =K2+L2 -> 176 | Q2: =M2+N2 -> 12 | R2: =G2+H2 -> 0
A3: 2174 | B3: 1954 | C3: Graduation | D3: Single | E3: 46344 | F3: =E3/1000 -> 46.344 | G3: 1 | H3: 1 | I3: 41706 | J3: 38 | K3: {=VLOOKUP(A3,Sales!$A$1:$E$2241,{2,3,4,5},0)} -> 1 | L3: 1 | M3: 1 | N3: 2 | O3: =2025-B3 -> 71 | P3: =K3+L3 -> 2 | Q3: =M3+N3 -> 3 | R3: =G3+H3 -> 2
A4: 4141 | B4: 1965 | C4: Graduation | D4: Together | E4: 71613 | F4: =E4/1000 -> 71.613 | G4: 0 | H4: 0 | I4: 41507 | J4: 26 | K4: {=VLOOKUP(A4,Sales!$A$1:$E$2241,{2,3,4,5},0)} -> 49 | L4: 21 | M4: 8 | N4: 10 | O4: =2025-B4 -> 60 | P4: =K4+L4 -> 70 | Q4: =M4+N4 -> 18 | R4: =G4+H4 -> 0
A5: 6182 | B5: 1984 | C5: Graduation | D5: Together | E5: 26646 | F5: =E5/1000 -> 26.646 | G5: 1 | H5: 0 | I5: 41680 | J5: 26 | K5: {=VLOOKUP(A5,Sales!$A$1:$E$2241,{2,3,4,5},0)} -> 4 | L5: 3 | M5: 2 | N5: 4 | O5: =2025-B5 -> 41 | P5: =K5+L5 -> 7 | Q5: =M5+N5 -> 6 | R5: =G5+H5 -> 1
A6: 5324 | B6: 1981 | C6: PhD | D6: Married | E6: 58293 | F6: =E6/1000 -> 58.293 | G6: 1 | H6: 0 | I6: 41658 | J6: 94 | K6: {=VLOOKUP(A6,Sales!$A$1:$E$2241,{2,3,4,5},0)} -> 43 | L6: 27 | M6: 5 | N6: 6 | O6: =2025-B6 -> 44 | P6: =K6+L6 -> 70 | Q6: =M6+N6 -> 11 | R6: =G6+H6 -> 1
A7: 7446 | B7: 1967 | C7: Master | D7: Together | E7: 62513 | F7: =E7/1000 -> 62.513 | G7: 0 | H7: 1 | I7: 41526 | J7: 16 | K7: {=VLOOKUP(A7,Sales!$A$1:$E$2241,{2,3,4,5},0)} -> 42 | L7: 42 | M7: 6 | N7: 10 | O7: =2025-B7 -> 58 | P7: =K7+L7 -> 84 | Q7: =M7+N7 -> 16 | R7: =G7+H7 -> 1
A8: 965 | B8: 1971 | C8: Graduation | D8: Divorced | E8: 55635 | F8: =E8/1000 -> 55.635 | G8: 0 | H8: 1 | I8: 41226 | J8: 34 | K8: {=VLOOKUP(A8,Sales!$A$1:$E$2241,{2,3,4,5},0)} -> 65 | L8: 49 | M8: 7 | N8: 7 | O8: =2025-B8 -> 54 | P8: =K8+L8 -> 114 | Q8: =M8+N8 -> 14 | R8: =G8+H8 -> 1
A9: 6177 | B9: 1985 | C9: PhD | D9: Married | E9: 33454 | F9: =E9/1000 -> 33.454 | G9: 1 | H9: 0 | I9: 41402 | J9: 32 | K9: {=VLOOKUP(A9,Sales!$A$1:$E$2241,{2,3,4,5},0)} -> 10 | L9: 1 | M9: 4 | N9: 4 | O9: =2025-B9 -> 40 | P9: =K9+L9 -> 11 | Q9: =M9+N9 -> 8 | R9: =G9+H9 -> 1
A10: 4855 | B10: 1974 | C10: PhD | D10: Together | E10: 30351 | F10: =E10/1000 -> 30.351 | G10: 1 | H10: 0 | I10: 41431 | J10: 19 | K10: {=VLOOKUP(A10,Sales!$A$1:$E$2241,{2,3,4,5},0)} -> 0 | L10: 3 | M10: 3 | N10: 2 | O10: =2025-B10 -> 51 | P10: =K10+L10 -> 3 | Q10: =M10+N10 -> 5 | R10: =G10+H10 -> 1
A11: 5899 | B11: 1950 | C11: PhD | D11: Together | E11: 5648 | F11: =E11/1000 -> 5.648 | G11: 1 | H11: 1 | I11: 41711 | J11: 68 | K11: {=VLOOKUP(A11,Sales!$A$1:$E$2241,{2,3,4,5},0)} -> 0 | L11: 1 | M11: 1 | N11: 0 | O11: =2025-B11 -> 75 | P11: =K11+L11 -> 1 | Q11: =M11+N11 -> 1 | R11: =G11+H11 -> 2
A12: 1994 | B12: 1983 | C12: Graduation | D12: Married | E12: ='Missing Values'!$F$5 -> 51381.5 | F12: =E12/1000 -> 51.3815 | G12: 1 | H12: 0 | I12: 41593 | J12: 11 | K12: {=VLOOKUP(A12,Sales!$A$1:$E$2241,{2,3,4,5},0)} -> 5 | L12: 2 | M12: 1 | N12: 2 | O12: =2025-B12 -> 42 | P12: =K12+L12 -> 7 | Q12: =M12+N12 -> 3 | R12: =G12+H12 -> 1
A13: 387 | B13: 1976 | C13: Basic | D13: Married | E13: 7500 | F13: =E13/1000 -> 7.5 | G13: 0 | H13: 0 | I13: 41226 | J13: 59 | K13: {=VLOOKUP(A13,Sales!$A$1:$E$2241,{2,3,4,5},0)} -> 16 | L13: 1 | M13: 2 | N13: 3 | O13: =2025-B13 -> 49 | P13: =K13+L13 -> 17 | Q13: =M13+N13 -> 5 | R13: =G13+H13 -> 0
A14: 2125 | B14: 1959 | C14: Graduation | D14: Divorced | E14: 63033 | F14: =E14/1000 -> 63.033 | G14: 0 | H14: 0 | I14: 41593 | J14: 82 | K14: {=VLOOKUP(A14,Sales!$A$1:$E$2241,{2,3,4,5},0)} -> 61 | L14: 112 | M14: 3 | N14: 8 | O14: =2025-B14 -> 66 | P14: =K14+L14 -> 173 | Q14: =M14+N14 -> 11 | R14: =G14+H14 -> 0
A15: 8180 | B15: 1952 | C15: Master | D15: Divorced | E15: 59354 | F15: =E15/1000 -> 59.354 | G15: 1 | H15: 1 | I15: 41593 | J15: 53 | K15: {=VLOOKUP(A15,Sales!$A$1:$E$2241,{2,3,4,5},0)} -> 2 | L15: 5 | M15: 6 | N15: 5 | O15: =2025-B15 -> 73 | P15: =K15+L15 -> 7 | Q15: =M15+N15 -> 11 | R15: =G15+H15 -> 2
A16: 2569 | B16: 1987 | C16: Graduation | D16: Married | E16: 17323 | F16: =E16/1000 -> 17.323 | G16: 0 | H16: 0 | I16: 41192 | J16: 38 | K16: {=VLOOKUP(A16,Sales!$A$1:$E$2241,{2,3,4,5},0)} -> 14 | L16: 1 | M16: 1 | N16: 3 | O16: =2025-B16 -> 38 | P16: =K16+L16 -> 15 | Q16: =M16+N16 -> 4 | R16: =G16+H16 -> 0
A17: 2114 | B17: 1946 | C17: PhD | D17: Single | E17: 82800 | F17: =E17/1000 -> 82.8 | G17: 0 | H17: 0 | I17: 41237 | J17: 23 | K17: {=VLOOKUP(A17,Sales!$A$1:$E$2241,{2,3,4,5},0)} -> 22 | L17: 68 | M17: 7 | N17: 12 | O17: =2025-B17 -> 79 | P17: =K17+L17 -> 90 | Q17: =M17+N17 -> 19 | R17: =G17+H17 -> 0
A18: 9736 | B18: 1980 | C18: Graduation | D18: Married | E18: 41850 | F18: =E18/1000 -> 41.85 | G18: 1 | H18: 1 | I18: 41267 | J18: 51 | K18: {=VLOOKUP(A18,Sales!$A$1:$E$2241,{2,3,4,5},0)} -> 5 | L18: 13 | M18: 3 | N18: 3 | O18: =2025-B18 -> 45 | P18: =K18+L18 -> 18 | Q18: =M18+N18 -> 6 | R18: =G18+H18 -> 2
A19: 4939 | B19: 1946 | C19: Graduation | D19: Together | E19: 37760 | F19: =E19/1000 -> 37.76 | G19: 0 | H19: 0 | I19: 41152 | J19: 20 | K19: {=VLOOKUP(A19,Sales!$A$1:$E$2241,{2,3,4,5},0)} -> 5 | L19: 12 | M19: 4 | N19: 6 | O19: =2025-B19 -> 79 | P19: =K19+L19 -> 17 | Q19: =M19+N19 -> 10 | R19: =G19+H19 -> 0
A20: 6565 | B20: 1949 | C20: Master | D20: Married | E20: 76995 | F20: =E20/1000 -> 76.995 | G20: 0 | H20: 1 | I20: 41361 | J20: 91 | K20: {=VLOOKUP(A20,Sales!$A$1:$E$2241,{2,3,4,5},0)} -> 80 | L20: 16 | M20: 11 | N20: 9 | O20: =2025-B20 -> 76 | P20: =K20+L20 -> 96 | Q20: =M20+N20 -> 20 | R20: =G20+H20 -> 1
A21: 2278 | B21: 1985 | C21: 2n Cycle | D21: Single | E21: 33812 | F21: =E21/1000 -> 33.812 | G21: 1 | H21: 0 | I21: 41216 | J21: 86 | K21: {=VLOOKUP(A21,Sales!$A$1:$E$2241,{2,3,4,5},0)} -> 17 | L21: 24 | M21: 2 | N21: 3 | O21: =2025-B21 -> 40 | P21: =K21+L21 -> 41 | Q21: =M21+N21 -> 5 | R21: =G21+H21 -> 1
A22: 9360 | B22: 1982 | C22: Graduation | D22: Married | E22: 37040 | F22: =E22/1000 -> 37.04 | G22: 0 | H22: 0 | I22: 41129 | J22: 41 | K22: {=VLOOKUP(A22,Sales!$A$1:$E$2241,{2,3,4,5},0)} -> 2 | L22: 38 | M22: 4 | N22: 5 | O22: =2025-B22 -> 43 | P22: =K22+L22 -> 40 | Q22: =M22+N22 -> 9 | R22: =G22+H22 -> 0
A23: 5376 | B23: 1979 | C23: Graduation | D23: Married | E23: 2447 | F23: =E23/1000 -> 2.447 | G23: 1 | H23: 0 | I23: 41280 | J23: 42 | K23: {=VLOOKUP(A23,Sales!$A$1:$E$2241,{2,3,4,5},0)} -> 1 | L23: 1 | M23: 0 | N23: 0 | O23: =2025-B23 -> 46 | P23: =K23+L23 -> 2 | Q23: =M23+N23 -> 0 | R23: =G23+H23 -> 1
A24: 1993 | B24: 1949 | C24: PhD | D24: Married | E24: 58607 | F24: =E24/1000 -> 58.607 | G24: 0 | H24: 1 | I24: 41266 | J24: 63 | K24: {=VLOOKUP(A24,Sales!$A$1:$E$2241,{2,3,4,5},0)} -> 0 | L24: 0 | M24: 2 | N24: 9 | O24: =2025-B24 -> 76 | P24: =K24+L24 -> 0 | Q24: =M24+N24 -> 11 | R24: =G24+H24 -> 1
... A28: 2404 | B28: 1976 | C28: Graduation | D28: Married | E28: 53359 | F28: =E28/1000 -> 53.359 | G28: 1 | H28: 1 | I28: 41421 | J28: 4 | K28: {=VLOOKUP(A28,Sales!$A$1:$E$2241,{2,3,4,5},0)} -> 4 | L28: 6 | M28: 5 | N28: 4 | O28: =2025-B28 -> 49 | P28: =K28+L28 -> 10 | Q28: =M28+N28 -> 9 | R28: =G28+H28 -> 2
A29: 5255 | B29: 1986 | C29: Graduation | D29: Single | E29: ='Missing Values'!$F$5 -> 51381.5 | F29: =E29/1000 -> 51.3815 | G29: 1 | H29: 0 | I29: 41325 | J29: 19 | K29: {=VLOOKUP(A29,Sales!$A$1:$E$2241,{2,3,4,5},0)} -> 1 | L29: 263 | M29: 27 | N29: 0 | O29: =2025-B29 -> 39 | P29: =K29+L29 -> 264 | Q29: =M29+N29 -> 27 | R29: =G29+H29 -> 1
A30: 9422 | B30: 1989 | C30: Graduation | D30: Married | E30: 38360 | F30: =E30/1000 -> 38.36 | G30: 1 | H30: 0 | I30: 41425 | J30: 26 | K30: {=VLOOKUP(A30,Sales!$A$1:$E$2241,{2,3,4,5},0)} -> 2 | L30: 21 | M30: 2 | N30: 4 | O30: =2025-B30 -> 36 | P30: =K30+L30 -> 23 | Q30: =M30+N30 -> 6 | R30: =G30+H30 -> 1
A31: 1966 | B31: 1965 | C31: PhD | D31: Married | E31: 84618 | F31: =E31/1000 -> 84.618 | G31: 0 | H31: 0 | I31: 41600 | J31: 96 | K31: {=VLOOKUP(A31,Sales!$A$1:$E$2241,{2,3,4,5},0)} -> 100 | L31: 66 | M31: 6 | N31: 10 | O31: =2025-B31 -> 60 | P31: =K31+L31 -> 166 | Q31: =M31+N31 -> 16 | R31: =G31+H31 -> 0
A32: 6864 | B32: 1989 | C32: Master | D32: Divorced | E32: 10979 | F32: =E32/1000 -> 10.979 | G32: 0 | H32: 0 | I32: 41781 | J32: 34 | K32: {=VLOOKUP(A32,Sales!$A$1:$E$2241,{2,3,4,5},0)} -> 4 | L32: 2 | M32: 3 | N32: 3 | O32: =2025-B32 -> 36 | P32: =K32+L32 -> 6 | Q32: =M32+N32 -> 6 | R32: =G32+H32 -> 0
A33: 3033 | B33: 1963 | C33: Master | D33: Together | E33: 38620 | F33: =E33/1000 -> 38.62 | G33: 0 | H33: 0 | I33: 41405 | J33: 56 | K33: {=VLOOKUP(A33,Sales!$A$1:$E$2241,{2,3,4,5},0)} -> 17 | L33: 22 | M33: 2 | N33: 3 | O33: =2025-B33 -> 62 | P33: =K33+L33 -> 39 | Q33: =M33+N33 -> 5 | R33: =G33+H33 -> 0
A34: 5710 | B34: 1970 | C34: Graduation | D34: Together | E34: 40548 | F34: =E34/1000 -> 40.548 | G34: 0 | H34: 1 | I34: 41192 | J34: 31 | K34: {=VLOOKUP(A34,Sales!$A$1:$E$2241,{2,3,4,5},0)} -> 0 | L34: 0 | M34: 2 | N34: 4 | O34: =2025-B34 -> 55 | P34: =K34+L34 -> 0 | Q34: =M34+N34 -> 6 | R34: =G34+H34 -> 1
A35: 7373 | B35: 1952 | C35: PhD | D35: Divorced | E35: 46610 | F35: =E35/1000 -> 46.61 | G35: 0 | H35: 2 | I35: 41211 | J35: 8 | K35: {=VLOOKUP(A35,Sales!$A$1:$E$2241,{2,3,4,5},0)} -> 12 | L35: 22 | M35: 4 | N35: 6 | O35: =2025-B35 -> 73 | P35: =K35+L35 -> 34 | Q35: =M35+N35 -> 10 | R35: =G35+H35 -> 2
A36: 8755 | B36: 1946 | C36: Master | D36: Married | E36: 68657 | F36: =E36/1000 -> 68.657 | G36: 0 | H36: 0 | I36: 41325 | J36: 4 | K36: {=VLOOKUP(A36,Sales!$A$1:$E$2241,{2,3,4,5},0)} -> 34 | L36: 68 | M36: 3 | N36: 9 | O36: =2025-B36 -> 79 | P36: =K36+L36 -> 102 | Q36: =M36+N36 -> 12 | R36: =G36+H36 -> 0
A37: 10738 | B37: 1951 | C37: Master | D37: Single | E37: 49389 | F37: =E37/1000 -> 49.389 | G37: 1 | H37: 1 | I37: 41515 | J37: 55 | K37: {=VLOOKUP(A37,Sales!$A$1:$E$2241,{2,3,4,5},0)} -> 0 | L37: 1 | M37: 2 | N37: 3 | O37: =2025-B37 -> 74 | P37: =K37+L37 -> 1 | Q37: =M37+N37 -> 5 | R37: =G37+H37 -> 2
A38: 4339 | B38: 1970 | C38: PhD | D38: Married | E38: 67353 | F38: =E38/1000 -> 67.353 | G38: 0 | H38: 1 | I38: 41639 | J38: 37 | K38: {=VLOOKUP(A38,Sales!$A$1:$E$2241,{2,3,4,5},0)} -> 17 | L38: 8 | M38: 5 | N38: 12 | O38: =2025-B38 -> 55 | P38: =K38+L38 -> 25 | Q38: =M38+N38 -> 17 | R38: =G38+H38 -> 1
A39: 10755 | B39: 1976 | C39: 2n Cycle | D39: Married | E39: 23718 | F39: =E39/1000 -> 23.718 | G39: 1 | H39: 0 | I39: 41519 | J39: 76 | K39: {=VLOOKUP(A39,Sales!$A$1:$E$2241,{2,3,4,5},0)} -> 3 | L39: 7 | M39: 3 | N39: 2 | O39: =2025-B39 -> 49 | P39: =K39+L39 -> 10 | Q39: =M39+N39 -> 5 | R39: =G39+H39 -> 1
A40: 8595 | B40: 1973 | C40: Graduation | D40: Widow | E40: 42429 | F40: =E40/1000 -> 42.429 | G40: 0 | H40: 1 | I40: 41681 | J40: 99 | K40: {=VLOOKUP(A40,Sales!$A$1:$E$2241,{2,3,4,5},0)} -> 0 | L40: 0 | M40: 1 | N40: 3 | O40: =2025-B40 -> 52 | P40: =K40+L40 -> 0 | Q40: =M40+N40 -> 4 | R40: =G40+H40 -> 1
A41: 2968 | B41: 1943 | C41: PhD | D41: Divorced | E41: 48948 | F41: =E41/1000 -> 48.948 | G41: 0 | H41: 0 | I41: 41306 | J41: 53 | K41: {=VLOOKUP(A41,Sales!$A$1:$E$2241,{2,3,4,5},0)} -> 8 | L41: 49 | M41: 7 | N41: 5 | O41: =2025-B41 -> 82 | P41: =K41+L41 -> 57 | Q41: =M41+N41 -> 12 | R41: =G41+H41 -> 0
... A44: 8430 | B44: 1957 | C44: Graduation | D44: Together | E44: 21994 | F44: =E44/1000 -> 21.994 | G44: 0 | H44: 1 | I44: 41267 | J44: 4 | K44: {=VLOOKUP(A44,Sales!$A$1:$E$2241,{2,3,4,5},0)} -> 0 | L44: 1 | M44: 0 | N44: 3 | O44: =2025-B44 -> 68 | P44: =K44+L44 -> 1 | Q44: =M44+N44 -> 3 | R44: =G44+H44 -> 1
A45: 7281 | B45: 1959 | C45: PhD | D45: Single | E45: ='Missing Values'!$F$5 -> 51381.5 | F45: =E45/1000 -> 51.3815 | G45: 0 | H45: 0 | I45: 41583 | J45: 80 | K45: {=VLOOKUP(A45,Sales!$A$1:$E$2241,{2,3,4,5},0)} -> 11 | L45: 2 | M45: 1 | N45: 4 | O45: =2025-B45 -> 66 | P45: =K45+L45 -> 13 | Q45: =M45+N45 -> 5 | R45: =G45+H45 -> 0
...

Sheet Missing Values
A1: Functions | B1: ID | C1: Year_Birth | D1: Education | E1: Marital_Status | F1: Income | G1: Kidhome | H1: Teenhome | I1: Dt_Customer | J1: Recency | K1: MntFruits | L1: MntSweetProducts | M1: NumWebPurchases | N1: NumStorePurchases
A2: CountA | B2: =COUNTA(Customer!A2:A2241) -> 2240 | C2: =COUNTA(Customer!B2:B2241) -> 2240 | D2: =COUNTA(Customer!C2:C2241) -> 2240 | E2: =COUNTA(Customer!D2:D2241) -> 2240 | F2: =COUNTA(Customer!E2:E2241) -> 2240 | G2: =COUNTA(Customer!G2:G2241) -> 2240 | H2: =COUNTA(Customer!H2:H2241) -> 2240 | I2: =COUNTA(Customer!I2:I2241) -> 2240 | J2: =COUNTA(Customer!J2:J2241) -> 2240 | K2: =COUNTA(Customer!K2:K2241) -> 2240 | L2: =COUNTA(Customer!L2:L2241) -> 2240 | M2: =COUNTA(Customer!M2:M2241) -> 2240 | N2: =COUNTA(Customer!N2:N2241) -> 2240
A3: CountBlank | B3: =COUNTBLANK(Customer!A2:A2241) -> 0 | C3: =COUNTBLANK(Customer!B2:B2241) -> 0 | D3: =COUNTBLANK(Customer!C2:C2241) -> 0 | E3: =COUNTBLANK(Customer!D2:D2241) -> 0 | F3: =COUNTBLANK(Customer!E2:E2241) -> 0 | G3: =COUNTBLANK(Customer!G2:G2241) -> 0 | H3: =COUNTBLANK(Customer!H2:H2241) -> 0 | I3: =COUNTBLANK(Customer!I2:I2241) -> 0 | J3: =COUNTBLANK(Customer!J2:J2241) -> 0 | K3: =COUNTBLANK(Customer!K2:K2241) -> 0 | L3: =COUNTBLANK(Customer!L2:L2241) -> 0 | M3: =COUNTBLANK(Customer!M2:M2241) -> 0 | N3: =COUNTBLANK(Customer!N2:N2241) -> 0
A4: Mean | F4: =AVERAGE(Customer!E2:E2241) -> 52237.975 | G4: =AVERAGE(Customer!G2:G2241) -> 0.44419643 | H4: =AVERAGE(Customer!H2:H2241) -> 0.50625 | J4: =AVERAGE(Customer!J2:J2241) -> 49.109375 | K4: =AVERAGE(Customer!K2:K2241) -> 26.302232 | L4: =AVERAGE(Customer!L2:L2241) -> 27.062946 | M4: =AVERAGE(Customer!M2:M2241) -> 4.0848214 | N4: =AVERAGE(Customer!N2:N2241) -> 5.7901786
A5: Median | F5: 51381.5 | G5: =MEDIAN(Customer!G2:G2241) -> 0 | H5: =MEDIAN(Customer!H2:H2241) -> 0 | J5: =MEDIAN(Customer!J2:J2241) -> 49 | K5: =MEDIAN(Customer!K2:K2241) -> 8 | L5: =MEDIAN(Customer!L2:L2241) -> 8 | M5: =MEDIAN(Customer!M2:M2241) -> 4 | N5: =MEDIAN(Customer!N2:N2241) -> 5
A6: Std Dev | F6: =STDEV(Customer!E2:E2241) -> 25037.956 | G6: =STDEV(Customer!G2:G2241) -> 0.5383981 | H6: =STDEV(Customer!H2:H2241) -> 0.54453823 | J6: =STDEV(Customer!J2:J2241) -> 28.962453 | K6: =STDEV(Customer!K2:K2241) -> 39.773434 | L6: =STDEV(Customer!L2:L2241) -> 41.280498 | M6: =STDEV(Customer!M2:M2241) -> 2.7787141 | N6: =STDEV(Customer!N2:N2241) -> 3.2509581
A7: Percentage - Std Dev & Mean | F7: =F6/F4 -> 0.47930563 | J7: =J6/J4 -> 0.58975405 | K7: =K6/K4 -> 1.5121695 | L7: =L6/L4 -> 1.5253512 | M7: =M6/M4 -> 0.68025352 | N7: =N6/N4 -> 0.56146077
F8: Use Median
A10: In a normal scenario if the std dev is more than 40% of mean then in that case median can be used to fill missing values.

Sheet Data Type Check
A1: ID | B1: Year_Birth | C1: Education | D1: Marital_Status | E1: Income | F1: Kidhome | G1: Teenhome | H1: Dt_Customer | I1: Recency | J1: MntFruits | K1: MntSweetProducts | L1: NumWebPurchases | M1: NumStorePurchases
A2: =TYPE(Customer!A2) -> 1 | B2: =TYPE(Customer!B2) -> 1 | C2: =TYPE(Customer!C2) -> 2 | D2: =TYPE(Customer!D2) -> 2 | E2: =TYPE(Customer!E2) -> 1 | F2: =TYPE(Customer!G2) -> 1 | G2: =TYPE(Customer!H2) -> 1 | H2: =TYPE(Customer!I2) -> 1 | I2: =TYPE(Customer!J2) -> 1 | J2: =TYPE(Customer!K2) -> 1 | K2: =TYPE(Customer!L2) -> 1 | L2: =TYPE(Customer!M2) -> 1 | M2: =TYPE(Customer!N2) -> 1
A3: =TYPE(Customer!A3) -> 1 | B3: =TYPE(Customer!B3) -> 1 | C3: =TYPE(Customer!C3) -> 2 | D3: =TYPE(Customer!D3) -> 2 | E3: =TYPE(Customer!E3) -> 1 | F3: =TYPE(Customer!G3) -> 1 | G3: =TYPE(Customer!H3) -> 1 | H3: =TYPE(Customer!I3) -> 1 | I3: =TYPE(Customer!J3) -> 1 | J3: =TYPE(Customer!K3) -> 1 | K3: =TYPE(Customer!L3) -> 1 | L3: =TYPE(Customer!M3) -> 1 | M3: =TYPE(Customer!N3) -> 1
A4: =TYPE(Customer!A4) -> 1 | B4: =TYPE(Customer!B4) -> 1 | C4: =TYPE(Customer!C4) -> 2 | D4: =TYPE(Customer!D4) -> 2 | E4: =TYPE(Customer!E4) -> 1 | F4: =TYPE(Customer!G4) -> 1 | G4: =TYPE(Customer!H4) -> 1 | H4: =TYPE(Customer!I4) -> 1 | I4: =TYPE(Customer!J4) -> 1 | J4: =TYPE(Customer!K4) -> 1 | K4: =TYPE(Customer!L4) -> 1 | L4: =TYPE(Customer!M4) -> 1 | M4: =TYPE(Customer!N4) -> 1
A5: =TYPE(Customer!A5) -> 1 | B5: =TYPE(Customer!B5) -> 1 | C5: =TYPE(Customer!C5) -> 2 | D5: =TYPE(Customer!D5) -> 2 | E5: =TYPE(Customer!E5) -> 1 | F5: =TYPE(Customer!G5) -> 1 | G5: =TYPE(Customer!H5) -> 1 | H5: =TYPE(Customer!I5) -> 1 | I5: =TYPE(Customer!J5) -> 1 | J5: =TYPE(Customer!K5) -> 1 | K5: =TYPE(Customer!L5) -> 1 | L5: =TYPE(Customer!M5) -> 1 | M5: =TYPE(Customer!N5) -> 1
A6: =TYPE(Customer!A6) -> 1 | B6: =TYPE(Customer!B6) -> 1 | C6: =TYPE(Customer!C6) -> 2 | D6: =TYPE(Customer!D6) -> 2 | E6: =TYPE(Customer!E6) -> 1 | F6: =TYPE(Customer!G6) -> 1 | G6: =TYPE(Customer!H6) -> 1 | H6: =TYPE(Customer!I6) -> 1 | I6: =TYPE(Customer!J6) -> 1 | J6: =TYPE(Customer!K6) -> 1 | K6: =TYPE(Customer!L6) -> 1 | L6: =TYPE(Customer!M6) -> 1 | M6: =TYPE(Customer!N6) -> 1
A7: =TYPE(Customer!A7) -> 1 | B7: =TYPE(Customer!B7) -> 1 | C7: =TYPE(Customer!C7) -> 2 | D7: =TYPE(Customer!D7) -> 2 | E7: =TYPE(Customer!E7) -> 1 | F7: =TYPE(Customer!G7) -> 1 | G7: =TYPE(Customer!H7) -> 1 | H7: =TYPE(Customer!I7) -> 1 | I7: =TYPE(Customer!J7) -> 1 | J7: =TYPE(Customer!K7) -> 1 | K7: =TYPE(Customer!L7) -> 1 | L7: =TYPE(Customer!M7) -> 1 | M7: =TYPE(Customer!N7) -> 1
A8: =TYPE(Customer!A8) -> 1 | B8: =TYPE(Customer!B8) -> 1 | C8: =TYPE(Customer!C8) -> 2 | D8: =TYPE(Customer!D8) -> 2 | E8: =TYPE(Customer!E8) -> 1 | F8: =TYPE(Customer!G8) -> 1 | G8: =TYPE(Customer!H8) -> 1 | H8: =TYPE(Customer!I8) -> 1 | I8: =TYPE(Customer!J8) -> 1 | J8: =TYPE(Customer!K8) -> 1 | K8: =TYPE(Customer!L8) -> 1 | L8: =TYPE(Customer!M8) -> 1 | M8: =TYPE(Customer!N8) -> 1
A9: =TYPE(Customer!A9) -> 1 | B9: =TYPE(Customer!B9) -> 1 | C9: =TYPE(Customer!C9) -> 2 | D9: =TYPE(Customer!D9) -> 2 | E9: =TYPE(Customer!E9) -> 1 | F9: =TYPE(Customer!G9) -> 1 | G9: =TYPE(Customer!H9) -> 1 | H9: =TYPE(Customer!I9) -> 1 | I9: =TYPE(Customer!J9) -> 1 | J9: =TYPE(Customer!K9) -> 1 | K9: =TYPE(Customer!L9) -> 1 | L9: =TYPE(Customer!M9) -> 1 | M9: =TYPE(Customer!N9) -> 1
A10: =TYPE(Customer!A10) -> 1 | B10: =TYPE(Customer!B10) -> 1 | C10: =TYPE(Customer!C10) -> 2 | D10: =TYPE(Customer!D10) -> 2 | E10: =TYPE(Customer!E10) -> 1 | F10: =TYPE(Customer!G10) -> 1 | G10: =TYPE(Customer!H10) -> 1 | H10: =TYPE(Customer!I10) -> 1 | I10: =TYPE(Customer!J10) -> 1 | J10: =TYPE(Customer!K10) -> 1 | K10: =TYPE(Customer!L10) -> 1 | L10: =TYPE(Customer!M10) -> 1 | M10: =TYPE(Customer!N10) -> 1
A11: =TYPE(Customer!A11) -> 1 | B11: =TYPE(Customer!B11) -> 1 | C11: =TYPE(Customer!C11) -> 2 | D11: =TYPE(Customer!D11) -> 2 | E11: =TYPE(Customer!E11) -> 1 | F11: =TYPE(Customer!G11) -> 1 | G11: =TYPE(Customer!H11) -> 1 | H11: =TYPE(Customer!I11) -> 1 | I11: =TYPE(Customer!J11) -> 1 | J11: =TYPE(Customer!K11) -> 1 | K11: =TYPE(Customer!L11) -> 1 | L11: =TYPE(Customer!M11) -> 1 | M11: =TYPE(Customer!N11) -> 1
A12: =TYPE(Customer!A12) -> 1 | B12: =TYPE(Customer!B12) -> 1 | C12: =TYPE(Customer!C12) -> 2 | D12: =TYPE(Customer!D12) -> 2 | E12: =TYPE(Customer!E12) -> 1 | F12: =TYPE(Customer!G12) -> 1 | G12: =TYPE(Customer!H12) -> 1 | H12: =TYPE(Customer!I12) -> 1 | I12: =TYPE(Customer!J12) -> 1 | J12: =TYPE(Customer!K12) -> 1 | K12: =TYPE(Customer!L12) -> 1 | L12: =TYPE(Customer!M12) -> 1 | M12: =TYPE(Customer!N12) -> 1
A13: =TYPE(Customer!A13) -> 1 | B13: =TYPE(Customer!B13) -> 1 | C13: =TYPE(Customer!C13) -> 2 | D13: =TYPE(Customer!D13) -> 2 | E13: =TYPE(Customer!E13) -> 1 | F13: =TYPE(Customer!G13) -> 1 | G13: =TYPE(Customer!H13) -> 1 | H13: =TYPE(Customer!I13) -> 1 | I13: =TYPE(Customer!J13) -> 1 | J13: =TYPE(Customer!K13) -> 1 | K13: =TYPE(Customer!L13) -> 1 | L13: =TYPE(Customer!M13) -> 1 | M13: =TYPE(Customer!N13) -> 1
... A2241: =TYPE(Customer!A2241) -> 1 | B2241: =TYPE(Customer!B2241) -> 1 | C2241: =TYPE(Customer!C2241) -> 2 | D2241: =TYPE(Customer!D2241) -> 2 | E2241: =TYPE(Customer!E2241) -> 1 | F2241: =TYPE(Customer!G2241) -> 1 | G2241: =TYPE(Customer!H2241) -> 1 | H2241: =TYPE(Customer!I2241) -> 1 | I2241: =TYPE(Customer!J2241) -> 1 | J2241: =TYPE(Customer!K2241) -> 1 | K2241: =TYPE(Customer!L2241) -> 1 | L2241: =TYPE(Customer!M2241) -> 1 | M2241: =TYPE(Customer!N2241) -> 1

Sheet Outliers
A1: Income | B1: Outlier | D1: Q1 | E1: =QUARTILE(A2:A2241,1) -> 35538.75
A2: 58138 | B2: =IF(OR(A2<$E$4,A2>$E$5),"Yes","No") -> No | D2: Q3 | E2: =QUARTILE(A2:A2241,3) -> 68289.75
A3: 46344 | B3: =IF(OR(A3<$E$4,A3>$E$5),"Yes","No") -> No | D3: IQR | E3: =E2-E1 -> 32751
A4: 71613 | B4: =IF(OR(A4<$E$4,A4>$E$5),"Yes","No") -> No | D4: Lower | E4: =E1-(1.5*E3) -> -13587.75
A5: 26646 | B5: =IF(OR(A5<$E$4,A5>$E$5),"Yes","No") -> No | D5: Upper | E5: =E2+(1.5*E3) -> 117416.25
A6: 58293 | B6: =IF(OR(A6<$E$4,A6>$E$5),"Yes","No") -> No
A7: 62513 | B7: =IF(OR(A7<$E$4,A7>$E$5),"Yes","No") -> No
A8: 55635 | B8: =IF(OR(A8<$E$4,A8>$E$5),"Yes","No") -> No
A9: 33454 | B9: =IF(OR(A9<$E$4,A9>$E$5),"Yes","No") -> No
A10: 30351 | B10: =IF(OR(A10<$E$4,A10>$E$5),"Yes","No") -> No | D10: Box & Whisker
A11: 5648 | B11: =IF(OR(A11<$E$4,A11>$E$5),"Yes","No") -> No
A12: ='Missing Values'!$F$5 -> 51381.5 | B12: =IF(OR(A12<$E$4,A12>$E$5),"Yes","No") -> No
A13: 7500 | B13: =IF(OR(A13<$E$4,A13>$E$5),"Yes","No") -> No
A14: 63033 | B14: =IF(OR(A14<$E$4,A14>$E$5),"Yes","No") -> No
A15: 59354 | B15: =IF(OR(A15<$E$4,A15>$E$5),"Yes","No") -> No
A16: 17323 | B16: =IF(OR(A16<$E$4,A16>$E$5),"Yes","No") -> No
A17: 82800 | B17: =IF(OR(A17<$E$4,A17>$E$5),"Yes","No") -> No
A18: 41850 | B18: =IF(OR(A18<$E$4,A18>$E$5),"Yes","No") -> No
A19: 37760 | B19: =IF(OR(A19<$E$4,A19>$E$5),"Yes","No") -> No
A20: 76995 | B20: =IF(OR(A20<$E$4,A20>$E$5),"Yes","No") -> No
A21: 33812 | B21: =IF(OR(A21<$E$4,A21>$E$5),"Yes","No") -> No
A22: 37040 | B22: =IF(OR(A22<$E$4,A22>$E$5),"Yes","No") -> No
A23: 2447 | B23: =IF(OR(A23<$E$4,A23>$E$5),"Yes","No") -> No
A24: 58607 | B24: =IF(OR(A24<$E$4,A24>$E$5),"Yes","No") -> No
... A28: 53359 | B28: =IF(OR(A28<$E$4,A28>$E$5),"Yes","No") -> No
A29: ='Missing Values'!$F$5 -> 51381.5 | B29: =IF(OR(A29<$E$4,A29>$E$5),"Yes","No") -> No
A30: 38360 | B30: =IF(OR(A30<$E$4,A30>$E$5),"Yes","No") -> No
A31: 84618 | B31: =IF(OR(A31<$E$4,A31>$E$5),"Yes","No") -> No
A32: 10979 | B32: =IF(OR(A32<$E$4,A32>$E$5),"Yes","No") -> No
A33: 38620 | B33: =IF(OR(A33<$E$4,A33>$E$5),"Yes","No") -> No
A34: 40548 | B34: =IF(OR(A34<$E$4,A34>$E$5),"Yes","No") -> No
A35: 46610 | B35: =IF(OR(A35<$E$4,A35>$E$5),"Yes","No") -> No
A36: 68657 | B36: =IF(OR(A36<$E$4,A36>$E$5),"Yes","No") -> No
A37: 49389 | B37: =IF(OR(A37<$E$4,A37>$E$5),"Yes","No") -> No
A38: 67353 | B38: =IF(OR(A38<$E$4,A38>$E$5),"Yes","No") -> No
A39: 23718 | B39: =IF(OR(A39<$E$4,A39>$E$5),"Yes","No") -> No
A40: 42429 | B40: =IF(OR(A40<$E$4,A40>$E$5),"Yes","No") -> No
A41: 48948 | B41: =IF(OR(A41<$E$4,A41>$E$5),"Yes","No") -> No
... A44: 21994 | B44: =IF(OR(A44<$E$4,A44>$E$5),"Yes","No") -> No
A45: ='Missing Values'!$F$5 -> 51381.5 | B45: =IF(OR(A45<$E$4,A45>$E$5),"Yes","No") -> No
...

Sheet Questions
A1: Univariate
A2: Which age group of customers are willing to buy the product?
A3: Which income range of customers will be willing to buy the product?
A4: What is the maximum amount of sweets and amount of fruits sold?(Range can be identified)
A5: What is the pattern of the customers buying the products of ABC company with kids?
A6: What is the pattern of total purchases of the customers?
A8: Bivariate
A9: What is the correlation between the amount of fruits and sweets?
A10: What is the correlation between income and the amount spent on fruits/sweets?
A11: What is the correlation between income and total purchase?
A12: What is the correlation between Age and total purchases?
A13: What is the correlation between TotalKidsHome and the amount spent on sweets/fruits?
... A15: By using the box plot concept, we can find the correlation between education and the amount spent on sweets/fruits.

Sheet Univariate
B3: Values
A4: Age | B4: # | C4: Avg Income
A5: 29-38 | B5: 147 | C5: 48698.044
A6: 39-48 | B6: 459 | C6: 47773.485
A7: 49-58 | B7: 724 | C7: 50093.394
A8: 59-68 | B8: 487 | C8: 55316.521
A9: 69-78 | B9: 380 | C9: 57848.317
A10: 79-88 | B10: 40 | C10: 63923.637
A11: Grand Total | B11: 2237 | C11: 52227.408
A18: Count of Income
A19: Income | B19: Total
A20: 0-10000 | B20: 29
A21: 10000-20000 | B21: 98
A22: 20000-30000 | B22: 243
A23: 30000-40000 | B23: 362
A24: 40000-50000 | B24: 328
A25: 50000-60000 | B25: 338
A26: 60000-70000 | B26: 334
A27: 70000-80000 | B27: 291
A28: 80000-90000 | B28: 163
A29: 90000-100000 | B29: 41
A30: >100000 | B30: 13
A31: Grand Total | B31: 2240
A42: Count of Total Amount
A43: Total Amount | B43: Total
A44: 0-9 | B44: 825
A45: 10-19 | B45: 306
A46: 20-29 | B46: 182
A47: 30-39 | B47: 104
A48: 40-49 | B48: 83
A49: 50-59 | B49: 78
A50: 60-69 | B50: 68
A51: 70-79 | B51: 45
A52: 80-89 | B52: 52
A53: 90-99 | B53: 50
A54: Grand Total | B54: 1793
A60: Count of Total Purchases
A61: Total Purchases | B61: Total
A62: 0-2 | B62: 25
A63: 3-5 | B63: 610
...

Sheet Bivariate
A1: CORRELATION
A2: Amt spend on fruits vs amt spent on sweets | B2: =CORREL(Customer!K2:K2241,Customer!L2:L2241) -> 0.56716394
A3: Income vs Total spending by customer | B3: =CORREL(Customer!E2:E2241,Customer!P2:P2241) -> 0.48859849
A4: Income vs Purchases | B4: =CORREL(Customer!E2:E2241,Customer!Q2:Q2241) -> 0.52933324
A5: Age vs Purchases | B5: =CORREL(Customer!O2:O2241,Customer!Q2:Q2241) -> 0.1567378
A6: Age vs Amount | B6: =CORREL(Customer!O2:O2241,Customer!P2:P2241) -> 0.020363795
A7: Kids vs amt spent | B7: =CORREL(Customer!R2:R2241,Customer!P2:P2241) -> -0.43929838
A23: Count of Marital_Status | B23: Marital_Status
A24: Education | B24: Divorced | C24: Married | D24: Single | E24: Together | F24: Widow | G24: Grand Total
A25: 2n Cycle | B25: 23 | C25: 81 | D25: 37 | E25: 57 | F25: 5 | G25: 203
A26: Basic | B26: 1 | C26: 20 | D26: 18 | E26: 14 | F26: 1 | G26: 54
A27: Graduation | B27: 119 | C27: 433 | D27: 252 | E27: 286 | F27: 35 | G27: 1125
A28: Master | B28: 37 | C28: 138 | D28: 75 | E28: 106 | F28: 12 | G28: 368
A29: PhD | B29: 52 | C29: 192 | D29: 98 | E29: 117 | F29: 24 | G29: 483
A30: Grand Total | B30: 232 | C30: 864 | D30: 480 | E30: 580 | F30: 77 | G30: 2233

Sheet Insights
A1: Univariate Analysis
A2: Age | B2: Most of customers are middle aged (49-58)
A3: Income | B3: 30k-80k
A4: Total amount | B4: Most of the customers spend $0-$9
A5: Total times purchased | B5: 3 to 5 times
A6: Kids | B6: Most of customers have 1 Kid
A7: Education | B7: Most of customers are graduated
A8: Marital Status | B8: Most of customers are married
A10: Bivariate
A11: Amt Fruits Vs Amt Sweets | B11: People who buy fruits, also tend to buy sweets (0.57 correlation)
A12: Income vs Amt spent | B12: With an increase in income, customers spend more (0.49 correl)
A13: Income vs Purchases | B13: With an increase in income, customers purchase more no of times (0.53 correl)
A14: Age vs Purchases | B14: Age does not impact no of purchases
A15: Age vs Total Amt | B15: No Impact
A16: Kids vs Total amt | B16: Less kids leads to more spending (-0.44 correl)

Sheet Dashboard
A1: 48-57 age, $30k to $80k, married and graduated people majorly become customers of ABC company Ltd.
A30: Total number of kids have impact on customers, average income doesn’t impact customer
A49: High customer count also result in higher purchase, which means customer count is correlated with purchase
A67: NEW PRODUCT LAUNCH
A68: For new product launch, we should target people with 0 total kids and also groups with higher income
A85: Currently, I already have customers who are
A86: 1. Middle aged
A87: 2. Married
A88: 3. Graduated
A89: 4. $30k to 80k
A91: Going forward, I will also target:
A92: 1. 0 Kids
A93: 2. Higher avg income

Sheet Sales
A1: ID | B1: MntFruits | C1: MntSweetProducts | D1: NumWebPurchases | E1: NumStorePurchases
A2: 4619 | B2: 2 | C2: 262 | D2: 27 | E2: 0
A3: 5255 | B3: 1 | C3: 263 | D3: 27 | E3: 0
A4: 10311 | B4: 4 | C4: 4 | D4: 25 | E4: 0
A5: 6237 | B5: 4 | C5: 2 | D5: 23 | E5: 1
A6: 7381 | B6: 153 | C6: 97 | D6: 11 | E6: 6
A7: 7966 | B7: 137 | C7: 22 | D7: 11 | E7: 11
A8: 4910 | B8: 134 | C8: 134 | D8: 11 | E8: 13
A9: 1951 | B9: 122 | C9: 129 | D9: 11 | E9: 8
A10: 7706 | B10: 104 | C10: 151 | D10: 11 | E10: 5
A11: 8931 | B11: 99 | C11: 149 | D11: 11 | E11: 10
A12: 1911 | B12: 97 | C12: 133 | D12: 11 | E12: 12
A13: 9743 | B13: 89 | C13: 35 | D13: 11 | E13: 8
... A2241: 2375 | B2241: 0 | C2241: 3 | D2241: 0 | E2241: 3
